Workbook

Sheet Tracker
A1: HOLY CROSS COLLEGE STA. ROSA, N.E., INC. — CHED 3-YEAR TRIMESTER APPLICATION — PROGRESS TRACKER
A2: Requirements taken from the Preliminary Requirement checklist held by the Office of Academic Affairs. Target filing with CHED Region III: 13 November 2026 (Council Resolution 2026-08-03). Yellow cells are for you to update: Status, % and Notes.
A4: # | B4: Requirement | C4: CHED reference | D4: Owner | E4: Support | F4: Due date | G4: Status | H4: % | I4: Notes
A5: AREA A — GOVERNANCE & SUBMISSION
A6: 1 | B6: Transmittal letter to CHED, with copy of the Council of Program Chairs Minutes approving the offering of the new program | C6: Checklist item 1 | D6: MIS Head Jayson R. Francisco | E6: Vice Dean Ken Gie Anthony G. Cruel (drafted both documents); VPAA Sta. Ines (signatory) | F6: 46277 | G6: For review | H6: 1 | I6: Transmittal letter accomplished and Minutes of the 27 Aug 2026 special meeting drafted by the Vice Dean, routed for signing (Res. 2026-08-01, -02, -03). Ownership transferred to the MIS Head on 3 Sep 2026 by direction of the Vice Dean. SIGNATORY CHECK: the CHED Region III Citizen's Charter requires the application letter to be signed by the Chairman of the Board of Trustees or the President, or an authorised representative — not by the VPAA. Confirm who signs before the letter is finalised.
A7: 2 | B7: CHED Program Evaluation — self-evaluation compilation against each programme's CHED Policies, Standards and Guidelines (PSG) | C7: Checklist item 2 | D7: Vice Dean Ken Gie Anthony G. Cruel | E7: All 8 Program Chairs (one PSG comparison each) | F7: 46318 | G7: In progress | H7: 0.5 | I7: RESOLVED 3 Sep 2026: there is no prescribed CHED form. It is a compilation the college prepares against each programme's PSG. Corroborated by the CHED Region III Citizen's Charter, which requires a duly accomplished self-evaluation form per programme on submission. Each of the 8 Chairs supplies their own programme's PSG comparison; the Vice Dean consolidates. 21 Sep 2026: BSA and BSAIS self-evaluations (Official and generated copies) now use the "First Year - Trimester 1" naming convention; the builder was updated to write it. 13 Oct 2026: BSA and BSAIS drafts regenerated as v1.1 (curricular finding complete; 40 programme-outcome mappings and the Year 1 teaching-load rows filled). 11 of 17 institutional requirements per programme still outstanding: faculty roster, library, facilities, internship, admission and retention, and the Sec. 20, 22 and 23 systems. 26 Oct 2026: the BSA and BSAIS Year 1 course syllabi that the self-evaluation cites are now drafted (see item 20 and 26).
A8: AREA B — INSTITUTIONAL FEASIBILITY (Feasibility study for trimestral calendar)
A9: 3 | B9: Philosophy and goals of the program | C9: Checklist item 3.1 | D9: Vice Dean Ken Gie Anthony G. Cruel | E9: VPAA Sta. Ines | F9: 46295 | G9: In progress | H9: 0.5 | I9: 23 Sep 2026: the description and goals of each programme are drafted in Section I of the BSA and BSAIS feasibility studies (BSA & BSAIS Outputs/Feasibility Study). The remaining six programmes still need theirs. 26 Oct 2026: v2 drafts of the BSA and BSAIS feasibility studies now replace the earlier versions (acceptability survey results added; Table 9 mean to be corrected at source).
A10: 4 | B10: Viability — demand for the graduates | C10: Checklist item 3.2.1 | D10: MIS Head Jayson R. Francisco | E10: All Program Chairs; Feasibility & Market Study Committee — full-time faculty, one per department | F10: 46304 | G10: Not started | H10: 0 | I10: Phase 2 of the project plan assigns market demand data gathering to MIS with the Chairs. 23 Sep 2026: Section III of the BSA and BSAIS feasibility studies carries the College's rationale on demand, flagged in the document itself as rationale and not survey findings. The market demand study supersedes it when available. Evidence now in Section III of both studies: 95% of BSA and BSAIS graduates are gainfully employed in work related to their field, on the College's own graduate survey; the first batch of CPALE examinees returned 4 passers out of 6. The survey instrument, period, population and respondents, and the PRC report of rating, must be attached as annexes. 23 Sep 2026: an acceptability survey on the proposed change is ready to run — questionnaire (form ref. HCC-VD-TRI-ACC-01, 23 Likert items in four parts plus preference and open questions) and a tabulation workbook that computes weighted means, verbal interpretations and an acceptability index as responses are encoded. In BSA & BSAIS Outputs/Acceptability Survey. Still to decide: who is asked and how they are chosen — CHED will ask. 23 Sep 2026: house standard set for this application — every document is built on the College's official letterhead template (HEADER-PORTRAIT-SHORT-LONG.docx) on short bond, 8.5 x 11. The feasibility studies and the acceptability survey are already on it. The sampling plan for the survey is in the tabulation workbook: whole-population for the small groups, Slovin at a 5% margin for the large ones. 26 Oct 2026: the Graduate Tracer Study for the Batch of May 2025 is in and replaces the earlier 95% figure. Thirty graduates, twenty-eight employed in work related to their field — 93% overall, BSA 19 of 20 (95%), BSAIS 9 of 10 (90%). Ten were hired within a month of graduating and fifteen within three months; all within eight. One entry marked not employed was confirmed employed by the Vice Dean. Both feasibility studies now carry these figures and the workbook is filed with them.
A11: 5 | B11: Viability — prospective students | C11: Checklist item 3.2.2 | D11: MIS Head Jayson R. Francisco | E11: Registrar Laila D. Sarmiento; Feasibility & Market Study Committee — full-time faculty, one per department | F11: 46304 | G11: Not started | H11: 0 | I11: 23 Sep 2026: the feasibility studies project first-year intake at 30 (BSA) and 25 (BSAIS) growing ten per cent a year, and ask the Registrar for six years of historical freshmen enrolment to confirm or revise it. The 93% employment result from the May 2025 tracer study (BSA 95%) strengthens the prospective-student case and is cited in Section III of both studies. 23 Sep 2026: an acceptability survey on the proposed change is ready to run — questionnaire (form ref. HCC-VD-TRI-ACC-01, 23 Likert items in four parts plus preference and open questions) and a tabulation workbook that computes weighted means, verbal interpretations and an acceptability index as responses are encoded. In BSA & BSAIS Outputs/Acceptability Survey. Still to decide: who is asked and how they are chosen — CHED will ask.
A12: 6 | B12: Viability — existing schools offering the same program within the area | C12: Checklist item 3.2.3 | D12: MIS Head Jayson R. Francisco | E12: All Program Chairs; Feasibility & Market Study Committee — full-time faculty, one per department | F12: 46304 | G12: Not started | H12: 0 | I12: 23 Sep 2026: the feasibility studies state that no other institution in the immediate area offers these programmes on a trimester calendar. This needs the competing-schools study behind it.
A13: 7 | B13: Location of the school in relation to factors that are not conducive to learning | C13: Checklist item 3.3 | D13: VPAA / VP Admin & Finance Dr. Raquel T. Sta. Ines | E13: MIS Head Jayson R. Francisco | F13: 46304 | G13: Not started | H13: 0 | I13: The VPAA also serves as VP for Administration and Finance, so this sits with her office. 23 Sep 2026: the location narrative (Central Luzon, Maharlika Highway, Clark Economic Zone, the Bulacan airport terminal) is drafted in Section III of both feasibility studies.
A14: 8 | B14: Schedule of tuition and other fees (trimestral) | C14: Checklist item 3.4 | D14: Finance Officer Dana Marcelo | E14: Vice Dean Ken Gie Anthony G. Cruel | F14: 46318 | G14: Not started | H14: 0 | I14: Phase 1 of the project plan calls for the trimestral fee distribution model to be initiated. 23 Sep 2026: a computation workbook is ready for the Finance Office — “BSA/BSAIS 3-Year Trimester — Tuition Computation.xlsx”. Enter the rate per unit, the miscellaneous fee per term, the expense ratios and the tax rate, and tuition, collections, expenses and net income compute for five years. Two decisions are still Finance's: the rates themselves, and whether miscellaneous fees are charged at the same amount per term under a three-term year or annualised across three terms.
A15: AREA C — ADMINISTRATORS, FACULTY & NON-TEACHING PERSONNEL
A16: 9 | B16: School administrator spreadsheet — name, educational qualifications (where and when obtained), position/designation, nature of appointment, status, rate of monthly salary, other benefits | C16: Checklist item 4.1 | D16: HR Officer Ellarein Richelle Dela Cruz | E16: Vice Dean Ken Gie Anthony G. Cruel | F16: 46318 | G16: Not started | H16: 0
A17: 10 | B17: School administrator — certified true copy of Transcript of Records, and appointment / notarized contract of employment / letter of commitment with confirmation | C17: Checklist item 4.2 | D17: HR Officer Ellarein Richelle Dela Cruz | E17: VPAA / VP Admin & Finance Dr. Raquel T. Sta. Ines | F17: 46325 | G17: Not started | H17: 0
A18: 11 | B18: Faculty spreadsheet (general education and major courses) — name, educational qualifications, field of specialization, course assignment, nature of appointment, status, rate of monthly salary, other benefits | C18: Checklist item 5.1 | D18: HR Officer Ellarein Richelle Dela Cruz | E18: All 8 Program Chairs (specialization and course assignment) | F18: 46318 | G18: Not started | H18: 0 | I18: Phase 1 of the project plan has HR issuing the call-out for faculty certified true copy Transcripts of Record. 21 Sep 2026: BSA and BSAIS course assignments for First Year - Trimester 1 to 3 are available from the Proposed Faculty Loading (BSA & BSAIS Outputs/Faculty Matrix & Loading).
A19: 12 | B19: Faculty — certified true copies of Transcripts of Record | C19: Checklist item 5.2 | D19: HR Officer Ellarein Richelle Dela Cruz | E19: All 8 Program Chairs | F19: 46325 | G19: Not started | H19: 0
A20: 13 | B20: Faculty — appointment / notarized contract of employment / letter of commitment with confirmation | C20: Checklist item 5.3 | D20: HR Officer Ellarein Richelle Dela Cruz | E20: VPAA Sta. Ines | F20: 46325 | G20: Not started | H20: 0
A21: 14 | B21: List of non-teaching personnel | C21: Checklist item 6 | D21: VPAA / VP Admin & Finance Dr. Raquel T. Sta. Ines | E21: HR Officer Ellarein Richelle Dela Cruz | F21: 46318 | G21: Not started | H21: 0 | I21: Checklist assigns this to Admin. There is no separate Admin Office Head — the VPAA holds the VP for Administration and Finance portfolio.
A22: AREA D — CURRICULUM (per program)
A23: 15 | B23: Curriculum — distribution of courses per trimester (9-term prospectus), BSA | C23: Checklist item 7.1 | D23: Vice Dean Ken Gie Anthony G. Cruel | E23: Vice Dean Ken Gie Anthony G. Cruel (compliance audit); MIS Head Jayson R. Francisco (repository) | F23: 46290 | G23: For review | H23: 1 | I23: Draft 9-trimester prospectus prepared by the Vice Dean — 191 total units across 9 terms. Must be recast onto the agreed template (see Reference): Course Code, Course Title, Lec Hrs, Lab Hrs, Total Hrs, Credit Units, Prerequisite(s), with a sub-total per trimester and the programme's own PSG cited in the header. TERM LENGTH DECIDED, 9 Sep 2026: 14 weeks per trimester, by the Council of Programme Chairs. The contact-hour standard moves with it from 54 to 56 hours per 3-unit subject, so a 3-unit subject runs 240 minutes a week and divides into whole periods (2 x 120, 3 x 80 or 4 x 60 minutes). MEETING DATE AND RESOLUTION NUMBER STILL TO BE SUPPLIED for the dossier. 21 Sep 2026: term headings renamed to the college convention "First Year - Trimester 1", "First Year - Trimester 2" … "Third Year - Trimester 3"; prerequisites now read "Completed Second Year" / "Completed Third Year - Trimester 1".
A24: 16 | B24: Curriculum — summary of units, BSA | C24: Checklist item 7.2 | D24: Vice Dean Ken Gie Anthony G. Cruel | E24: Vice Dean Ken Gie Anthony G. Cruel (compliance audit); MIS Head Jayson R. Francisco (repository) | F24: 46295 | G24: For review | H24: 1 | I24: Unit summary computed in the draft: Yr1 67, Yr2 67, Yr3 57. Two term totals still carry unresolved formulas — verify before finalising. TERM LENGTH DECIDED, 9 Sep 2026: 14 weeks per trimester, by the Council of Programme Chairs. The contact-hour standard moves with it from 54 to 56 hours per 3-unit subject, so a 3-unit subject runs 240 minutes a week and divides into whole periods (2 x 120, 3 x 80 or 4 x 60 minutes). MEETING DATE AND RESOLUTION NUMBER STILL TO BE SUPPLIED for the dossier.
A25: 17 | B25: Updated trimester curriculum — list of subjects with GE and Specialized identified, BSA | C25: Checklist item 9.1 | D25: Vice Dean Ken Gie Anthony G. Cruel | E25: Vice Dean Ken Gie Anthony G. Cruel (compliance audit); MIS Head Jayson R. Francisco (repository) | F25: 46295 | G25: For review | H25: 1 | I25: General education courses are identifiable by code in the draft prospectus; the formal GE versus Specialised tagging sheet is still to be produced.
A26: 18 | B26: Updated trimester curriculum — sample schedule (Trimesters 1, 2 and 3), BSA | C26: Checklist item 9.2 | D26: Vice Dean Ken Gie Anthony G. Cruel | E26: Vice Dean Ken Gie Anthony G. Cruel (compliance audit); MIS Head Jayson R. Francisco (repository) | F26: 46304 | G26: For review | H26: 1 | I26: 21 Sep 2026: PROPOSED SCHEDULE OF CLASSES built for First Year - Trimester 1, 2 and 3 (BSA and BSAIS share one First Year section, 1-BSA-A / 1-BSAIS-A), with the matching PROPOSED FACULTY LOADING. Each trimester carries 31 contact hours a week and 23 units, Monday to Thursday only; Friday is kept free for consultation, make-up classes and student activities. A 3-unit course meets 4 hours a week (2 x 2-hour meetings, MW or TTH), which gives the settled 56 hours over 14 weeks, examination weeks included. Signatories: prepared by the Program Chair, reviewed by the College Dean, approved by the VPAA. Files: BSA & BSAIS Outputs/Sample Schedule/Proposed Schedule of Classes - First Year, Trimesters 1-3 (BSA-BSAIS) and BSA & BSAIS Outputs/Faculty Matrix & Loading/Proposed Faculty Loading - First Year, Trimesters 1-3 (BSA-BSAIS), Word and PDF. NOT YET BUILT: Second Year and Third Year schedules — raise with the Vice Dean if CHED expects all nine trimesters rather than one year's Trimesters 1, 2 and 3. Rooms are provisional (ML 401 for lecture, ML 211 for PATH-FIT).
A27: 19 | B27: Curriculum — course descriptions, BSA | C27: Checklist item 7.3 | D27: Vice Dean Ken Gie Anthony G. Cruel | E27: Vice Dean Ken Gie Anthony G. Cruel (compliance audit); MIS Head Jayson R. Francisco (repository); General Education Syllabi Pool (20 shared GE, PATH-FIT, NSTP and CLE courses, written once for all 8 programs); Business Cluster Pool (shared business, economics and law courses); Course teachers named in the Proposed Faculty Loading, First Year Trimesters 1–3 — J.R. Francisco, CPA; J.R. Empay, CPA; D.N. Santiago, CPA; R. Cruz, CPA (professional courses), each writing the description and syllabus for the courses that loading gives them; M. Germino, N. Tolosa, S.M. Calma, L. Ramos, M. Mequiabas, X. Villamayor, F. Ilag, J. Jamlang (GE, PATH-FIT, NSTP and CLE). Still no full-time faculty besides the Chair — see Open Item 9 | F27: 46304 | G27: For review | H27: 1 | I27: Awaiting the curriculum template. CAPACITY RISK: the programme-specialised courses here have no full-time author other than the Chair.
A28: 20 | B28: Curriculum — course syllabi (outcomes-based), BSA | C28: Checklist item 7.4 | D28: Vice Dean Ken Gie Anthony G. Cruel | E28: Vice Dean Ken Gie Anthony G. Cruel (compliance audit); MIS Head Jayson R. Francisco (repository); General Education Syllabi Pool (20 shared GE, PATH-FIT, NSTP and CLE courses, written once for all 8 programs); Business Cluster Pool (shared business, economics and law courses); Course teachers named in the Proposed Faculty Loading, First Year Trimesters 1–3 — J.R. Francisco, CPA; J.R. Empay, CPA; D.N. Santiago, CPA; R. Cruz, CPA (professional courses), each writing the description and syllabus for the courses that loading gives them; M. Germino, N. Tolosa, S.M. Calma, L. Ramos, M. Mequiabas, X. Villamayor, F. Ilag, J. Jamlang (GE, PATH-FIT, NSTP and CLE). Still no full-time faculty besides the Chair — see Open Item 9 | F28: 46311 | G28: For review | H28: 1 | I28: ASSESSMENT SCHEME confirmed by the Vice Dean, 3 Sep 2026: two examinations per term (midterm and final), one required monthly assessment, plus regular quizzes and activities. Every syllabus must carry this scheme. CAPACITY RISK: the programme-specialised courses here have no full-time author other than the Chair. 26 Oct 2026: all BSA course syllabi drafted on the OBE template (14-week / 56-hour basis, midterm Week 7, final Week 14) in BSA & BSAIS Outputs/Sample Syllabus/Drafts for Review; references left blank; subject-expert review pending. AE7-INT 400-hour deployment still to be confirmed. 26 Oct 2026: the syllabus drafts now carry the course teacher. Prepared by / Subject Instructor on each of the 24 First Year courses is the faculty member the Proposed Faculty Loading assigns to it — 20 changed from the Vice Dean, 4 were already right. Reviewed by (Chair), Recommended by (Vice Dean) and Approved by (Dean) are unchanged. The 51 Second and Third Year syllabi still read Vice Dean as instructor, because no loading has been drawn for those years yet.
A29: 21 | B29: Curriculum — distribution of courses per trimester (9-term prospectus), BSAIS | C29: Checklist item 7.1 | D29: Vice Dean Ken Gie Anthony G. Cruel | E29: Vice Dean Ken Gie Anthony G. Cruel (compliance audit); MIS Head Jayson R. Francisco (repository) | F29: 46290 | G29: For review | H29: 1 | I29: Draft 9-trimester prospectus prepared by the Vice Dean — 185 total units across 9 terms. Must be recast onto the agreed template (see Reference): Course Code, Course Title, Lec Hrs, Lab Hrs, Total Hrs, Credit Units, Prerequisite(s), with a sub-total per trimester and the programme's own PSG cited in the header. TERM LENGTH DECIDED, 9 Sep 2026: 14 weeks per trimester, by the Council of Programme Chairs. The contact-hour standard moves with it from 54 to 56 hours per 3-unit subject, so a 3-unit subject runs 240 minutes a week and divides into whole periods (2 x 120, 3 x 80 or 4 x 60 minutes). MEETING DATE AND RESOLUTION NUMBER STILL TO BE SUPPLIED for the dossier. 21 Sep 2026: term headings renamed to the college convention "First Year - Trimester 1", "First Year - Trimester 2" … "Third Year - Trimester 3"; prerequisites now read "Completed Second Year" / "Completed Third Year - Trimester 1".
A30: 22 | B30: Curriculum — summary of units, BSAIS | C30: Checklist item 7.2 | D30: Vice Dean Ken Gie Anthony G. Cruel | E30: Vice Dean Ken Gie Anthony G. Cruel (compliance audit); MIS Head Jayson R. Francisco (repository) | F30: 46295 | G30: For review | H30: 1 | I30: Unit summary computed in the draft: Yr1 67, Yr2 67, Yr3 51. Two term totals still carry unresolved formulas — verify before finalising. TERM LENGTH DECIDED, 9 Sep 2026: 14 weeks per trimester, by the Council of Programme Chairs. The contact-hour standard moves with it from 54 to 56 hours per 3-unit subject, so a 3-unit subject runs 240 minutes a week and divides into whole periods (2 x 120, 3 x 80 or 4 x 60 minutes). MEETING DATE AND RESOLUTION NUMBER STILL TO BE SUPPLIED for the dossier.
A31: 23 | B31: Updated trimester curriculum — list of subjects with GE and Specialized identified, BSAIS | C31: Checklist item 9.1 | D31: Vice Dean Ken Gie Anthony G. Cruel | E31: Vice Dean Ken Gie Anthony G. Cruel (compliance audit); MIS Head Jayson R. Francisco (repository) | F31: 46295 | G31: For review | H31: 1 | I31: General education courses are identifiable by code in the draft prospectus; the formal GE versus Specialised tagging sheet is still to be produced.
A32: 24 | B32: Updated trimester curriculum — sample schedule (Trimesters 1, 2 and 3), BSAIS | C32: Checklist item 9.2 | D32: Vice Dean Ken Gie Anthony G. Cruel | E32: Vice Dean Ken Gie Anthony G. Cruel (compliance audit); MIS Head Jayson R. Francisco (repository) | F32: 46304 | G32: For review | H32: 1 | I32: 21 Sep 2026: PROPOSED SCHEDULE OF CLASSES built for First Year - Trimester 1, 2 and 3 (BSA and BSAIS share one First Year section, 1-BSA-A / 1-BSAIS-A), with the matching PROPOSED FACULTY LOADING. Each trimester carries 31 contact hours a week and 23 units, Monday to Thursday only; Friday is kept free for consultation, make-up classes and student activities. A 3-unit course meets 4 hours a week (2 x 2-hour meetings, MW or TTH), which gives the settled 56 hours over 14 weeks, examination weeks included. Signatories: prepared by the Program Chair, reviewed by the College Dean, approved by the VPAA. Files: BSA & BSAIS Outputs/Sample Schedule/Proposed Schedule of Classes - First Year, Trimesters 1-3 (BSA-BSAIS) and BSA & BSAIS Outputs/Faculty Matrix & Loading/Proposed Faculty Loading - First Year, Trimesters 1-3 (BSA-BSAIS), Word and PDF. NOT YET BUILT: Second Year and Third Year schedules — raise with the Vice Dean if CHED expects all nine trimesters rather than one year's Trimesters 1, 2 and 3. Rooms are provisional (ML 401 for lecture, ML 211 for PATH-FIT).
A33: 25 | B33: Curriculum — course descriptions, BSAIS | C33: Checklist item 7.3 | D33: Vice Dean Ken Gie Anthony G. Cruel | E33: Vice Dean Ken Gie Anthony G. Cruel (compliance audit); MIS Head Jayson R. Francisco (repository); General Education Syllabi Pool (20 shared GE, PATH-FIT, NSTP and CLE courses, written once for all 8 programs); Business Cluster Pool (shared business, economics and law courses); Course teachers named in the Proposed Faculty Loading, First Year Trimesters 1–3 — J.R. Francisco, CPA; J.R. Empay, CPA; D.N. Santiago, CPA; R. Cruz, CPA (professional courses), each writing the description and syllabus for the courses that loading gives them; M. Germino, N. Tolosa, S.M. Calma, L. Ramos, M. Mequiabas, X. Villamayor, F. Ilag, J. Jamlang (GE, PATH-FIT, NSTP and CLE). Still no full-time faculty besides the Chair — see Open Item 9 | F33: 46304 | G33: For review | H33: 1 | I33: Awaiting the curriculum template. CAPACITY RISK: the programme-specialised courses here have no full-time author other than the Chair.
A34: 26 | B34: Curriculum — course syllabi (outcomes-based), BSAIS | C34: Checklist item 7.4 | D34: Vice Dean Ken Gie Anthony G. Cruel | E34: Vice Dean Ken Gie Anthony G. Cruel (compliance audit); MIS Head Jayson R. Francisco (repository); General Education Syllabi Pool (20 shared GE, PATH-FIT, NSTP and CLE courses, written once for all 8 programs); Business Cluster Pool (shared business, economics and law courses); Course teachers named in the Proposed Faculty Loading, First Year Trimesters 1–3 — J.R. Francisco, CPA; J.R. Empay, CPA; D.N. Santiago, CPA; R. Cruz, CPA (professional courses), each writing the description and syllabus for the courses that loading gives them; M. Germino, N. Tolosa, S.M. Calma, L. Ramos, M. Mequiabas, X. Villamayor, F. Ilag, J. Jamlang (GE, PATH-FIT, NSTP and CLE). Still no full-time faculty besides the Chair — see Open Item 9 | F34: 46311 | G34: For review | H34: 1 | I34: ASSESSMENT SCHEME confirmed by the Vice Dean, 3 Sep 2026: two examinations per term (midterm and final), one required monthly assessment, plus regular quizzes and activities. Every syllabus must carry this scheme. CAPACITY RISK: the programme-specialised courses here have no full-time author other than the Chair. 26 Oct 2026: all BSAIS course syllabi drafted on the OBE template (14-week / 56-hour basis, midterm Week 7, final Week 14) in BSA & BSAIS Outputs/Sample Syllabus/Drafts for Review; references left blank; subject-expert review pending. AE7-INT 400-hour deployment still to be confirmed. 26 Oct 2026: the syllabus drafts now carry the course teacher. Prepared by / Subject Instructor on each of the 24 First Year courses is the faculty member the Proposed Faculty Loading assigns to it — 20 changed from the Vice Dean, 4 were already right. Reviewed by (Chair), Recommended by (Vice Dean) and Approved by (Dean) are unchanged. The 51 Second and Third Year syllabi still read Vice Dean as instructor, because no loading has been drawn for those years yet.
... A70: 62 | B70: Curriculum — course syllabi (outcomes-based), BSED | C70: Checklist item 7.4 | D70: Program Chair Kent E. Garcia | E70: Vice Dean Ken Gie Anthony G. Cruel (compliance audit); MIS Head Jayson R. Francisco (repository); General Education Syllabi Pool (20 shared GE, PATH-FIT, NSTP and CLE courses, written once for all 8 programs); 14 full-time BSED faculty | F70: 46311 | G70: In progress | H70: 0 | I70: ASSESSMENT SCHEME confirmed by the Vice Dean, 3 Sep 2026: two examinations per term (midterm and final), one required monthly assessment, plus regular quizzes and activities. Every syllabus must carry this scheme.
A71: AREA E — LIBRARY
A72: 63 | B72: Librarian — qualification and status per appointment | C72: Checklist item 8.1 | D72: Library Lead Annabelle Pastrana | E72: HR Officer Ellarein Richelle Dela Cruz | F72: 46295 | G72: Not started | H72: 0 | I72: There is no appointed head librarian. Annabelle Pastrana acts as Library Lead in the meantime; Sta. Cruz and Bernardo complete the library team. This item asks for the librarian's qualification and status per appointment, so a designation memo naming Ms. Pastrana as Officer-in-Charge must be issued and attached — the name alone will not close this row.
A73: 64 | B73: List of library facilities | C73: Checklist item 8.2 | D73: Library Lead Annabelle Pastrana | E73: VPAA / VP Admin & Finance Dr. Raquel T. Sta. Ines | F73: 46295 | G73: Not started | H73: 0
A74: 65 | B74: Library seating capacity | C74: Checklist item 8.3 | D74: Library Lead Annabelle Pastrana | E74: VPAA / VP Admin & Finance Dr. Raquel T. Sta. Ines | F74: 46295 | G74: Not started | H74: 0
A75: 66 | B75: Library collections spreadsheet (books, journals, magazines, dictionaries, almanacs) — author, title, year of publication, number of volumes | C75: Checklist item 8.4.1 | D75: Library Lead Annabelle Pastrana | E75: Sta. Cruz (also Teacher Education faculty); Bernardo (also Hospitality Management faculty); Library Collection Committee — full-time faculty, one per department | F75: 46304 | G75: Not started | H75: 0
A76: 67 | B76: List of 5 non-duplicated titles per subject in the curriculum, published within the last 5 years | C76: Checklist item 8.4.2 | D76: Library Lead Annabelle Pastrana | E76: Sta. Cruz; Bernardo; All 8 Program Chairs (subject lists); Library Collection Committee — full-time faculty, one per department | F76: 46311 | G76: Not started | H76: 0 | I76: Project plan reads this as titles published 2021-2026. Depends on the curriculum subject lists (item 9.1) for all 8 programs.
...

Sheet Assignments
A1: ASSIGNMENT MATRIX — WHO OWNS WHAT
A2: Item numbers refer to the # column on the Tracker sheet. Owner means one person is accountable for delivering that document; Support means they must supply input, but the Owner answers for it. Only full-time faculty are tasked — the 21 part-time faculty remain on the Faculty sheet for checklist item 5.1 and carry no project work, but every faculty member, part-time included, must still lodge their own transcript and contract with HR for items 12 and 13. Because BSA, BSAIS and BSCS have no full-time faculty besides their Chair, manpower is borrowed through two college-wide pools. As of 13 September 2026 every full-time faculty member has a named, answerable task: the 12 pool writers are allocated specific courses below, and the other 15 hold a counted task until their Chair publishes the departmental allocation under items 76 to 80, due 25 September 2026.
A4: Person or Office | B4: Role in project | C4: Items owned | D4: Items supporting | E4: Nearest due date
A5: LEADS, OFFICES AND PROGRAM CHAIRS
A6: Vice Dean Ken Gie Anthony G. Cruel | B6: Co-Lead, CHED Application Task Force; Program Chair for BSA and BSAIS; overall compliance audit and filing. Sole full-time author for the programme-specialised accountancy and AIS courses — see Open Item 9 | C6: 16 items: #2–3, 15–26, 71–72 | D6: 53 items: #1, 4, 6, 8–9, 11–12, 27–62, 67, 70, 73–80 | E6: =IF(COUNTIFS(Tracker!$D$5:$D$90,$A6,Tracker!$G$5:$G$90,"<>Done")=0,"—",_xlfn.MINIFS(Tracker!$F$5:$F$90,Tracker!$D$5:$D$90,$A6,Tracker!$G$5:$G$90,"<>Done"))
A7: MIS Head Jayson R. Francisco | B7: Co-Lead, CHED Application Task Force; owner of the transmittal letter and minutes package (item 1, transferred 3 Sep 2026); chairs the Feasibility & Market Study Committee; document repository and binder assembly; carries the outstanding CHED Region III questions (item 73) | C7: 6 items: #1, 4–6, 70, 73 | D7: 50 items: #7, 15–62, 72 | E7: =IF(COUNTIFS(Tracker!$D$5:$D$90,$A7,Tracker!$G$5:$G$90,"<>Done")=0,"—",_xlfn.MINIFS(Tracker!$F$5:$F$90,Tracker!$D$5:$D$90,$A7,Tracker!$G$5:$G$90,"<>Done"))
A8: VPAA / VP Admin & Finance Dr. Raquel T. Sta. Ines | B8: Presiding officer, Council of Program Chairs; signatory and approving authority; also holds the VP for Administration and Finance portfolio, so the non-teaching personnel list and the school location report sit with her office | C8: 2 items: #7, 14 | D8: 7 items: #1, 3, 10, 13, 64–65, 71 | E8: =IF(COUNTIFS(Tracker!$D$5:$D$90,$A8,Tracker!$G$5:$G$90,"<>Done")=0,"—",_xlfn.MINIFS(Tracker!$F$5:$F$90,Tracker!$D$5:$D$90,$A8,Tracker!$G$5:$G$90,"<>Done"))
A9: Dean Dr. Almario B. Garcia | B9: Co-Lead, CHED Application Task Force (added 3 Sep 2026 by direction of the Vice Dean, alongside the Vice Dean and the MIS Head); College Dean; executive endorsement of the completed dossier | C9: None — support role only | D9: 1 item: #71 | E9: =IF(COUNTIFS(Tracker!$D$5:$D$90,$A9,Tracker!$G$5:$G$90,"<>Done")=0,"—",_xlfn.MINIFS(Tracker!$F$5:$F$90,Tracker!$D$5:$D$90,$A9,Tracker!$G$5:$G$90,"<>Done"))
A10: HR Officer Ellarein Richelle Dela Cruz | B10: Owner of all administrator, faculty and personnel records | C10: 5 items: #9–13 | D10: 2 items: #14, 63 | E10: =IF(COUNTIFS(Tracker!$D$5:$D$90,$A10,Tracker!$G$5:$G$90,"<>Done")=0,"—",_xlfn.MINIFS(Tracker!$F$5:$F$90,Tracker!$D$5:$D$90,$A10,Tracker!$G$5:$G$90,"<>Done"))
A11: Library Lead Annabelle Pastrana | B11: Acting Library Lead — owner of the complete library section; chairs the Library Collection Committee | C11: 7 items: #63–69 | D11: — | E11: =IF(COUNTIFS(Tracker!$D$5:$D$90,$A11,Tracker!$G$5:$G$90,"<>Done")=0,"—",_xlfn.MINIFS(Tracker!$F$5:$F$90,Tracker!$D$5:$D$90,$A11,Tracker!$G$5:$G$90,"<>Done"))
A12: Program Chair Kent E. Garcia | B12: Program Chair, Teacher Education — BEED and BSED curriculum; chairs their Curriculum & Syllabi Committee; his department supplies the General Education Syllabi Pool for the whole college; LEAD of the General Education Syllabi Pool (item 74) — allocates the 20 shared courses across its 8 writers, issues the common syllabus template, sets the internal hand-in dates and reports slippage to the Vice Dean | C12: 14 items: #51–62, 74, 79 | D12: 6 items: #2, 4, 6, 11–12, 67 | E12: =IF(COUNTIFS(Tracker!$D$5:$D$90,$A12,Tracker!$G$5:$G$90,"<>Done")=0,"—",_xlfn.MINIFS(Tracker!$F$5:$F$90,Tracker!$D$5:$D$90,$A12,Tracker!$G$5:$G$90,"<>Done"))
A13: Program Chair Ranilo S. Castillo II | B13: Program Chair, Business Administration — BSBA curriculum; his department supplies the Business Cluster Pool for BSA, BSAIS and BSHM; LEAD of the Business Cluster Pool (item 75) — fixes the definitive shared-course list, allocates it across its 4 writers, sets the internal hand-in dates and reports slippage to the Vice Dean | C13: 8 items: #27–32, 75, 80 | D13: 7 items: #2, 4, 6, 11–12, 67, 74 | E13: =IF(COUNTIFS(Tracker!$D$5:$D$90,$A13,Tracker!$G$5:$G$90,"<>Done")=0,"—",_xlfn.MINIFS(Tracker!$F$5:$F$90,Tracker!$D$5:$D$90,$A13,Tracker!$G$5:$G$90,"<>Done"))
A14: Program Chair John Philip N. Diamat | B14: Program Chair, Computer Science — BSCS curriculum. Sole full-time author for the programme-specialised computer science courses — see Open Item 9 | C14: 7 items: #33–38, 78 | D14: 7 items: #2, 4, 6, 11–12, 67, 74 | E14: =IF(COUNTIFS(Tracker!$D$5:$D$90,$A14,Tracker!$G$5:$G$90,"<>Done")=0,"—",_xlfn.MINIFS(Tracker!$F$5:$F$90,Tracker!$D$5:$D$90,$A14,Tracker!$G$5:$G$90,"<>Done"))
A15: Program Chair Stephanie S. Ciasico | B15: Program Chair, Hospitality Management — BSHM curriculum; chairs its Curriculum & Syllabi Committee | C15: 7 items: #39–44, 77 | D15: 8 items: #2, 4, 6, 11–12, 67, 74–75 | E15: =IF(COUNTIFS(Tracker!$D$5:$D$90,$A15,Tracker!$G$5:$G$90,"<>Done")=0,"—",_xlfn.MINIFS(Tracker!$F$5:$F$90,Tracker!$D$5:$D$90,$A15,Tracker!$G$5:$G$90,"<>Done"))
A16: Program Chair Samantha Rose C. Pisto | B16: Program Chair, Criminal Justice Education — BSCRIM curriculum; chairs its Curriculum & Syllabi Committee | C16: 7 items: #45–50, 76 | D16: 7 items: #2, 4, 6, 11–12, 67, 74 | E16: =IF(COUNTIFS(Tracker!$D$5:$D$90,$A16,Tracker!$G$5:$G$90,"<>Done")=0,"—",_xlfn.MINIFS(Tracker!$F$5:$F$90,Tracker!$D$5:$D$90,$A16,Tracker!$G$5:$G$90,"<>Done"))
A17: Finance Officer Dana Marcelo | B17: Trimestral tuition and fee schedule | C17: 1 item: #8 | D17: — | E17: =IF(COUNTIFS(Tracker!$D$5:$D$90,$A17,Tracker!$G$5:$G$90,"<>Done")=0,"—",_xlfn.MINIFS(Tracker!$F$5:$F$90,Tracker!$D$5:$D$90,$A17,Tracker!$G$5:$G$90,"<>Done"))
A18: Registrar Laila D. Sarmiento | B18: Enrolment and prospective-student data for the feasibility study | C18: None — support role only | D18: 1 item: #5 | E18: =IF(COUNTIFS(Tracker!$D$5:$D$90,$A18,Tracker!$G$5:$G$90,"<>Done")=0,"—",_xlfn.MINIFS(Tracker!$F$5:$F$90,Tracker!$D$5:$D$90,$A18,Tracker!$G$5:$G$90,"<>Done"))
A19: ACCOUNTANCY & AIS — Curriculum & Syllabi Committee for BSA and BSAIS (chaired by Vice Dean Cruel) (NO full-time faculty besides the Chair; 5 part-time not tasked)
A20: Francisco, Josephine Rose, CPA | B20: Named in the Proposed Faculty Loading, First Year Trimesters 1–3 — teaches AE13-FAR Financial Accounting and Reporting (T1), AE14-CFAS Conceptual Framework and Accounting Standards (T2). Writes the course description and outcomes-based syllabus for those courses. | C20: None — support role only | D20: 4 items: #19–20, 25–26 | E20: —
A21: Empay, Jan Rhommer, CPA | B21: Named in the Proposed Faculty Loading, First Year Trimesters 1–3 — teaches CBME 1 Operations Management and TQM (T1), AE1-BL1 Law on Obligations and Contracts (T3). Writes the course description and outcomes-based syllabus for those courses. | C21: None — support role only | D21: 4 items: #19–20, 25–26
A22: Santiago, Decirae Nicole, CPA | B22: Named in the Proposed Faculty Loading, First Year Trimesters 1–3 — teaches AE4-MGT1 Management Science (T3). Writes the course description and outcomes-based syllabus for those courses. | C22: None — support role only | D22: 4 items: #19–20, 25–26
A23: Cruz, Rommel, CPA | B23: Named in the Proposed Faculty Loading, First Year Trimesters 1–3 — teaches AE19-FINMGT Financial Management (T3). Writes the course description and outcomes-based syllabus for those courses. | C23: None — support role only | D23: 4 items: #19–20, 25–26
A24: — still no full-time faculty besides the Chair — | B24: The four above are part-time. The General Education, PE, NSTP and CLE courses of the First Year loading are written by the pool writers listed under Teacher Education and Criminal Justice Education. The Article VI full-time faculty requirement is still open — see Open Item 9. | C24: — | D24: —
A25: BUSINESS ADMINISTRATION — Curriculum & Syllabi Committee for BSBA (chaired by Chair Castillo) (4 full-time faculty tasked; 1 part-time not tasked)
A26: Aquino, Ann Jellie B. | B26: Business Cluster Pool writer (item 75) — writes the course description AND the OBE syllabus for 3 courses: AE11-ECO1 Managerial Economics; AE12-ECO2 Economic Development; AE5-IBT International Business and Trade. 6 documents, one set serving BSA, BSAIS, BSBA and BSHM. Candidate list, to be confirmed by Chair Castillo against the BSBA and BSHM prospectuses. To Chair Castillo: descriptions 9 Oct, syllabi 16 Oct 2026. Also Curriculum & Syllabi — BSBA, and a share of the BSBA major courses under item 80. [FT, 24 units, 6 preps this semester] | C26: None — support role only | D26: 13 items: #4–6, 19–20, 25–26, 31–32, 43–44, 75, 80 | E26: =IF(MIN(IF(Tracker!$G$10="Done",99999,Tracker!$F$10),IF(Tracker!$G$11="Done",99999,Tracker!$F$11),IF(Tracker!$G$12="Done",99999,Tracker!$F$12),IF(Tracker!$G$27="Done",99999,Tracker!$F$27),IF(Tracker!$G$28="Done",99999,Tracker!$F$28),IF(Tracker!$G$33="Done",99999,Tracker!$F$33),IF(Tracker!$G$34="Done",99999,Tracker!$F$34),IF(Tracker!$G$39="Done",99999,Tracker!$F$39),IF(Tracker!$G$40="Done",99999,Tracker!$F$40),IF(Tracker!$G$51="Done",99999,Tracker!$F$51),IF(Tracker!$G$52="Done",99999,Tracker!$F$52))=99999,"—",MIN(IF(Tracker!$G$10="Done",99999,Tracker!$F$10),IF(Tracker!$G$11="Done",99999,Tracker!$F$11),IF(Tracker!$G$12="Done",99999,Tracker!$F$12),IF(Tracker!$G$27="Done",99999,Tracker!$F$27),IF(Tracker!$G$28="Done",99999,Tracker!$F$28),IF(Tracker!$G$33="Done",99999,Tracker!$F$33),IF(Tracker!$G$34="Done",99999,Tracker!$F$34),IF(Tracker!$G$39="Done",99999,Tracker!$F$39),IF(Tracker!$G$40="Done",99999,Tracker!$F$40),IF(Tracker!$G$51="Done",99999,Tracker!$F$51),IF(Tracker!$G$52="Done",99999,Tracker!$F$52)))
A27: Bauat, Jhosalyn | B27: Business Cluster Pool writer (item 75) — writes the course description AND the OBE syllabus for 4 courses: CBME 1 Operations Management and TQM; CBME 2 Strategic Management; AE4-MGT1 Management Science; PE1-HBO Human Behavior in Organizations. 8 documents, one set serving BSA, BSAIS, BSBA and BSHM. Candidate list, to be confirmed by Chair Castillo against the BSBA and BSHM prospectuses. To Chair Castillo: descriptions 9 Oct, syllabi 16 Oct 2026. Also Curriculum & Syllabi — BSBA, and a share of the BSBA major courses under item 80. [FT, 24 units, 6 preps this semester] | C27: None — support role only | D27: 10 items: #19–20, 25–26, 31–32, 43–44, 75, 80 | E27: =IF(MIN(IF(Tracker!$G$27="Done",99999,Tracker!$F$27),IF(Tracker!$G$28="Done",99999,Tracker!$F$28),IF(Tracker!$G$33="Done",99999,Tracker!$F$33),IF(Tracker!$G$34="Done",99999,Tracker!$F$34),IF(Tracker!$G$39="Done",99999,Tracker!$F$39),IF(Tracker!$G$40="Done",99999,Tracker!$F$40),IF(Tracker!$G$51="Done",99999,Tracker!$F$51),IF(Tracker!$G$52="Done",99999,Tracker!$F$52))=99999,"—",MIN(IF(Tracker!$G$27="Done",99999,Tracker!$F$27),IF(Tracker!$G$28="Done",99999,Tracker!$F$28),IF(Tracker!$G$33="Done",99999,Tracker!$F$33),IF(Tracker!$G$34="Done",99999,Tracker!$F$34),IF(Tracker!$G$39="Done",99999,Tracker!$F$39),IF(Tracker!$G$40="Done",99999,Tracker!$F$40),IF(Tracker!$G$51="Done",99999,Tracker!$F$51),IF(Tracker!$G$52="Done",99999,Tracker!$F$52)))
A28: Dela Cruz, Jacqueline | B28: Business Cluster Pool writer (item 75) — writes the course description AND the OBE syllabus for 3 courses: AE19-FINMGT Financial Management; AE18-FINMKT Financial Markets; AE10-GOV Governance, Business Ethics, Risk Management and Internal Control. 6 documents, one set serving BSA, BSAIS, BSBA and BSHM. Candidate list, to be confirmed by Chair Castillo against the BSBA and BSHM prospectuses. To Chair Castillo: descriptions 9 Oct, syllabi 16 Oct 2026. Also Curriculum & Syllabi — BSBA, and a share of the BSBA major courses under item 80. [FT, 24 units, 5 preps this semester] | C28: None — support role only | D28: 12 items: #19–20, 25–26, 31–32, 43–44, 66–67, 75, 80 | E28: =IF(MIN(IF(Tracker!$G$27="Done",99999,Tracker!$F$27),IF(Tracker!$G$28="Done",99999,Tracker!$F$28),IF(Tracker!$G$33="Done",99999,Tracker!$F$33),IF(Tracker!$G$34="Done",99999,Tracker!$F$34),IF(Tracker!$G$39="Done",99999,Tracker!$F$39),IF(Tracker!$G$40="Done",99999,Tracker!$F$40),IF(Tracker!$G$51="Done",99999,Tracker!$F$51),IF(Tracker!$G$52="Done",99999,Tracker!$F$52),IF(Tracker!$G$75="Done",99999,Tracker!$F$75),IF(Tracker!$G$76="Done",99999,Tracker!$F$76))=99999,"—",MIN(IF(Tracker!$G$27="Done",99999,Tracker!$F$27),IF(Tracker!$G$28="Done",99999,Tracker!$F$28),IF(Tracker!$G$33="Done",99999,Tracker!$F$33),IF(Tracker!$G$34="Done",99999,Tracker!$F$34),IF(Tracker!$G$39="Done",99999,Tracker!$F$39),IF(Tracker!$G$40="Done",99999,Tracker!$F$40),IF(Tracker!$G$51="Done",99999,Tracker!$F$51),IF(Tracker!$G$52="Done",99999,Tracker!$F$52),IF(Tracker!$G$75="Done",99999,Tracker!$F$75),IF(Tracker!$G$76="Done",99999,Tracker!$F$76)))
A29: Salas, Kristine Joy | B29: Business Cluster Pool writer (item 75) — writes the course description AND the OBE syllabus for 3 courses: AE1-BL1 Law on Obligations and Contracts; AE2-BL2 Business Laws and Regulations; AE3-BL3 Regulatory Framework and Legal Issues in Business. 6 documents, one set serving BSA, BSAIS, BSBA and BSHM. Candidate list, to be confirmed by Chair Castillo against the BSBA and BSHM prospectuses. To Chair Castillo: descriptions 9 Oct, syllabi 16 Oct 2026. Also Curriculum & Syllabi — BSBA, and a share of the BSBA major courses under item 80. [FT, 24 units, 6 preps this semester] | C29: None — support role only | D29: 10 items: #19–20, 25–26, 31–32, 43–44, 75, 80 | E29: =IF(MIN(IF(Tracker!$G$27="Done",99999,Tracker!$F$27),IF(Tracker!$G$28="Done",99999,Tracker!$F$28),IF(Tracker!$G$33="Done",99999,Tracker!$F$33),IF(Tracker!$G$34="Done",99999,Tracker!$F$34),IF(Tracker!$G$39="Done",99999,Tracker!$F$39),IF(Tracker!$G$40="Done",99999,Tracker!$F$40),IF(Tracker!$G$51="Done",99999,Tracker!$F$51),IF(Tracker!$G$52="Done",99999,Tracker!$F$52))=99999,"—",MIN(IF(Tracker!$G$27="Done",99999,Tracker!$F$27),IF(Tracker!$G$28="Done",99999,Tracker!$F$28),IF(Tracker!$G$33="Done",99999,Tracker!$F$33),IF(Tracker!$G$34="Done",99999,Tracker!$F$34),IF(Tracker!$G$39="Done",99999,Tracker!$F$39),IF(Tracker!$G$40="Done",99999,Tracker!$F$40),IF(Tracker!$G$51="Done",99999,Tracker!$F$51),IF(Tracker!$G$52="Done",99999,Tracker!$F$52)))
A30: CRIMINAL JUSTICE EDUCATION — Curriculum & Syllabi Committee for BSCRIM (chaired by Chair Pisto) (5 full-time faculty tasked; 1 part-time not tasked)
A31: Arimbuyutan, Jazzele M. | B31: Curriculum & Syllabi — BSCRIM; Feasibility & Market Study [FT, 21 units, 4 preps this semester] | C31: None — support role only | D31: 6 items: #4–6, 49–50, 76 | E31: =IF(MIN(IF(Tracker!$G$10="Done",99999,Tracker!$F$10),IF(Tracker!$G$11="Done",99999,Tracker!$F$11),IF(Tracker!$G$12="Done",99999,Tracker!$F$12),IF(Tracker!$G$57="Done",99999,Tracker!$F$57),IF(Tracker!$G$58="Done",99999,Tracker!$F$58))=99999,"—",MIN(IF(Tracker!$G$10="Done",99999,Tracker!$F$10),IF(Tracker!$G$11="Done",99999,Tracker!$F$11),IF(Tracker!$G$12="Done",99999,Tracker!$F$12),IF(Tracker!$G$57="Done",99999,Tracker!$F$57),IF(Tracker!$G$58="Done",99999,Tracker!$F$58)))
A32: Dela Cruz, Jhon Allen R. | B32: Curriculum & Syllabi — BSCRIM [FT, 22 units, 5 preps this semester] | C32: None — support role only | D32: 3 items: #49–50, 76 | E32: =IF(MIN(IF(Tracker!$G$57="Done",99999,Tracker!$F$57),IF(Tracker!$G$58="Done",99999,Tracker!$F$58))=99999,"—",MIN(IF(Tracker!$G$57="Done",99999,Tracker!$F$57),IF(Tracker!$G$58="Done",99999,Tracker!$F$58)))
A33: Diaz, Pamela B. | B33: Curriculum & Syllabi — BSCRIM [FT, 22 units, 5 preps this semester] | C33: None — support role only | D33: 3 items: #49–50, 76 | E33: =IF(MIN(IF(Tracker!$G$57="Done",99999,Tracker!$F$57),IF(Tracker!$G$58="Done",99999,Tracker!$F$58))=99999,"—",MIN(IF(Tracker!$G$57="Done",99999,Tracker!$F$57),IF(Tracker!$G$58="Done",99999,Tracker!$F$58)))
A34: Pamiloza, Honey Mica R. | B34: Curriculum & Syllabi — BSCRIM [FT, 21 units, 4 preps this semester] | C34: None — support role only | D34: 3 items: #49–50, 76 | E34: =IF(MIN(IF(Tracker!$G$57="Done",99999,Tracker!$F$57),IF(Tracker!$G$58="Done",99999,Tracker!$F$58))=99999,"—",MIN(IF(Tracker!$G$57="Done",99999,Tracker!$F$57),IF(Tracker!$G$58="Done",99999,Tracker!$F$58)))
A35: Ramos, Leandro M. | B35: Curriculum & Syllabi — BSCRIM; Library Collection [FT, 18 units, 4 preps this semester] | C35: None — support role only | D35: 5 items: #49–50, 66–67, 76 | E35: =IF(MIN(IF(Tracker!$G$57="Done",99999,Tracker!$F$57),IF(Tracker!$G$58="Done",99999,Tracker!$F$58),IF(Tracker!$G$75="Done",99999,Tracker!$F$75),IF(Tracker!$G$76="Done",99999,Tracker!$F$76))=99999,"—",MIN(IF(Tracker!$G$57="Done",99999,Tracker!$F$57),IF(Tracker!$G$58="Done",99999,Tracker!$F$58),IF(Tracker!$G$75="Done",99999,Tracker!$F$75),IF(Tracker!$G$76="Done",99999,Tracker!$F$76)))
A36: COMPUTER SCIENCE — Curriculum & Syllabi Committee for BSCS (chaired by Chair Diamat) (1 full-time faculty tasked; 5 part-time not tasked)
A37: Cristobal, Teofilo G. | B37: Curriculum & Syllabi — BSCS [FT, 24 units, 3 preps this semester] | C37: None — support role only | D37: 3 items: #37–38, 78 | E37: =IF(MIN(IF(Tracker!$G$45="Done",99999,Tracker!$F$45),IF(Tracker!$G$46="Done",99999,Tracker!$F$46))=99999,"—",MIN(IF(Tracker!$G$45="Done",99999,Tracker!$F$45),IF(Tracker!$G$46="Done",99999,Tracker!$F$46)))
A38: HOSPITALITY MANAGEMENT — Curriculum & Syllabi Committee for BSHM (chaired by Chair Ciasico) (3 full-time faculty tasked; 5 part-time not tasked)
A39: Bernardo, Romeo DG | B39: Curriculum & Syllabi — BSHM; Library Collection [FT, 21 units, 4 preps this semester] | C39: None — support role only | D39: 7 items: #43–44, 66–69, 77 | E39: =IF(MIN(IF(Tracker!$G$51="Done",99999,Tracker!$F$51),IF(Tracker!$G$52="Done",99999,Tracker!$F$52),IF(Tracker!$G$75="Done",99999,Tracker!$F$75),IF(Tracker!$G$76="Done",99999,Tracker!$F$76),IF(Tracker!$G$77="Done",99999,Tracker!$F$77),IF(Tracker!$G$78="Done",99999,Tracker!$F$78))=99999,"—",MIN(IF(Tracker!$G$51="Done",99999,Tracker!$F$51),IF(Tracker!$G$52="Done",99999,Tracker!$F$52),IF(Tracker!$G$75="Done",99999,Tracker!$F$75),IF(Tracker!$G$76="Done",99999,Tracker!$F$76),IF(Tracker!$G$77="Done",99999,Tracker!$F$77),IF(Tracker!$G$78="Done",99999,Tracker!$F$78)))
A40: Dela Cruz, Jonathan | B40: Curriculum & Syllabi — BSHM; Feasibility & Market Study [FT, 18 units, 4 preps this semester] | C40: None — support role only | D40: 6 items: #4–6, 43–44, 77 | E40: =IF(MIN(IF(Tracker!$G$10="Done",99999,Tracker!$F$10),IF(Tracker!$G$11="Done",99999,Tracker!$F$11),IF(Tracker!$G$12="Done",99999,Tracker!$F$12),IF(Tracker!$G$51="Done",99999,Tracker!$F$51),IF(Tracker!$G$52="Done",99999,Tracker!$F$52))=99999,"—",MIN(IF(Tracker!$G$10="Done",99999,Tracker!$F$10),IF(Tracker!$G$11="Done",99999,Tracker!$F$11),IF(Tracker!$G$12="Done",99999,Tracker!$F$12),IF(Tracker!$G$51="Done",99999,Tracker!$F$51),IF(Tracker!$G$52="Done",99999,Tracker!$F$52)))
A41: Geronimo, Jing Feng A., LPT | B41: Curriculum & Syllabi — BSHM [FT, 24 units, 4 preps this semester] | C41: None — support role only | D41: 3 items: #43–44, 77 | E41: =IF(MIN(IF(Tracker!$G$51="Done",99999,Tracker!$F$51),IF(Tracker!$G$52="Done",99999,Tracker!$F$52))=99999,"—",MIN(IF(Tracker!$G$51="Done",99999,Tracker!$F$51),IF(Tracker!$G$52="Done",99999,Tracker!$F$52)))
...

Sheet Reference
A1: REFERENCE — SOURCES, CITATIONS, COMMITTEES AND OPEN ITEMS
A2: Everything in the Tracker traces back to one of the source documents below. Nothing has been added from general practice. Where a requirement is unclear, it is listed as an Open Item rather than guessed. The committee and borrowing structure in section F is an internal proposal for the Vice Dean's approval — it is not a CHED requirement.
A4: Section | B4: Detail
A5: A. SOURCE DOCUMENTS USED
A6: Preliminary Requirement checklist | B6: The 9-section documentary checklist held by the Office of Academic Affairs (items 1 to 9, including sub-items 3.1-3.4, 4.1-4.2, 5.1-5.3, 7.1-7.4, 8.1-8.4.4, 9.1-9.2). Sole source of Tracker items 1 to 69.
A7: Minutes of the Special Meeting of the Council of Program Chairs | B7: 27 August 2026, 10:00-11:30 AM, Office of the VPAA. Presided by VPAA Dr. Raquel T. Sta. Ines, technically facilitated by MIS Head Jayson R. Francisco, MIT, prepared by Vice Dean Ken Gie Anthony G. Cruel, CPA, MBA. Dean Dr. Almario B. Garcia on official leave.
A8: Internal project implementation plan | B8: Four-phase plan with hard deadlines of 12 Sep, 16 Oct, 30 Oct and 13 Nov 2026. Source of Tracker items 70 to 72 and of the delegation pattern used for owners.
A9: Draft trimester curriculum workbook | B9: Draft 9-term prospectus for BSA (191 units) and BSAIS (185 units), proposed AY 2027-2028 academic calendar, and the sample schedule sheet carrying the contact-hour computation. All 8 programmes are now at the same draft stage. NOTE: the calendar in this workbook was drawn on three terms of FIFTEEN academic weeks. The Council decided 14 weeks on 9 Sep 2026, so the calendar must be redrawn — including the enrolment, grade-processing and graduation dates — before any weekly schedule grid is finalised.
A10: CHED Region III Citizen's Charter (verified 3 Sep 2026) | B10: Official CHED source located and read on 3 September 2026. Its checklist for Application for Initial Permit (GP), Government Recognition (GR) and Certificate of Program Compliance (COPC) for Undergraduate Programs contains 18 numbered requirements. Items 1 and 5 to 10 correspond almost word for word to the internal Preliminary Requirement checklist - the same feasibility study headings, the same administrator and faculty spreadsheet fields, the same curriculum breakdown, and the same 3,000 and 5,000 library figures. Nine further requirements on the CHED list do not appear on the internal one: see Open Item 2. Source: https://chedro3.ched.gov.ph/wp-content/uploads/2021/01/CHEDROIII-Updated-Citizens-Charter.pdf
A11: 7.1 Distribution of Courses per Trimester — BSCRIM | B11: Received 3 Sep 2026 as the working template for checklist item 7.1, and as a complete BSCRIM prospectus in its own right (192 units, effective AY 2027-2028, citing CMO 05 s.2018 and CMO 20 s.2013). Not yet a final template - still for discussion. Its structure is set out in section C2 below.
A12: Faculty Roster, First Semester AY 2026-2027 | B12: 55 unique faculty (34 full-time, 21 part-time) across six departments, with course counts, units, weekly hours and preps. Prepared by Vice Dean Cruel, recommended by Dean Garcia, approved by VPAA Sta. Ines. Source of the Faculty sheet and of the committee membership in section E.
A14: B. COUNCIL RESOLUTIONS (27 AUGUST 2026)
A15: Resolution No. 2026-08-01 | B15: Endorsement of the proposed transition of BSA, BSAIS, BSBA, BSCS, BSHM, BSCRIM, BEED and BSED from the four-year semestral model to a 3-Year Trimester System, targeted to commence in AY 2027-2028, subject to CHED requirements.
A16: Resolution No. 2026-08-02 | B16: New curriculum to apply initially to incoming first-year students from AY 2027-2028. Students admitted earlier continue under their year-of-admission prospectus, subject to an approved transition and teach-out plan covering irregular, returning and transferee students.
A17: Resolution No. 2026-08-03 | B17: Mobilisation of the CHED Application Task Force, co-led by Vice Dean Cruel and MIS Head Francisco under the supervision of the Office of the VPAA. Target completion and submission of the consolidated dossier on or before 13 November 2026.
A19: C. CHED ISSUANCES AND AUTHORITY
A20: CMO No. 27 and CMO No. 30, series of 2017 | B20: Cited in the draft curriculum workbook as the basis for BSA and BSAIS contact hours: at least 14 contact hours per unit offered, which is 42 hours for a 3-unit subject. This is the regulatory FLOOR.
A21: College standard: 54 hours per 3-unit subject (superseded) | B21: SUPERSEDED 9 Sep 2026. Was 54 hours, set by the Vice Dean on 3 Sep 2026 when the term length was still open. Now 56 hours per 3-unit subject — see the Contact-hour standard entry in section D2.
A22: No CMO governs the checklist | B22: The internal Preliminary Requirement checklist carries no CMO number, series year or annex - and neither does CHED's own version. The CHED Region III Citizen's Charter presents the same requirements as a GPR Checklist and cites only Section 8 of Republic Act No. 7722, the Higher Education Act of 1994, as the general authority. So the missing CMO is not an omission by the college. Every Tracker row is cited to a checklist item number, which matches how CHED itself presents them. See Open Item 3.
A24: C2. THE CURRICULUM TEMPLATE (from the BSCRIM submission, 3 Sep 2026 - not yet final)
A25: Header | B25: Programme name in full. 'Effective Academic Year 2027-2028'. A References line citing that programme's own PSG - BSCRIM uses CMO 05 s.2018 and CMO 20 s.2013; BSA and BSAIS use CMO 27 and CMO 30 s.2017. This is how each row in the dossier gets a real citation: per programme, from its own PSG.
A26: Year groupings | B26: Three named years - the BSCRIM draft uses YEAR I: CORE FOUNDATIONS, YEAR II: PROFESSIONAL SUBJECTS, YEAR III: SPECIALIZATION - each holding three trimesters, numbered Trimester 1 through 9 straight through.
A27: Table columns | B27: Course Code | Course Title | Lec Hrs | Lab Hrs | Total Hrs | Credit Units | Prerequisite(s). One table per trimester, closing with a Sub-Total row that foots all four numeric columns.
A28: Summary table (checklist item 7.2) | B28: Units by category code, then the total: the BSCRIM draft gives GEC 33 (GE Core plus Rizal), GEE 15, PE 8, NSTP 6, Core 19, Major 105, OJT 6, total 192.
A29: Closing note | B29: 'Registration in any course is allowed only upon passing the prerequisite(s) of the said course, if any. A course enrolled in violation of this rule will not be given any credit regardless of the grade obtained.'
A30: Sign-off chain | B30: Prepared by: Programme Chairperson. Reviewed by: ALMARIO B. GARCIA, Ph.D., College Dean. Approved by: RAQUEL T. STA INES, Ph.D., Vice President for Academic Affairs. Every programme's item 7.1 follows this route.
A31: UNRESOLVED - what basis are the Hrs columns? | B31: In the BSCRIM draft a 3-unit lecture course reads 3 Lec Hrs, 3 Total Hrs. Those are WEEKLY hours on the old semestral convention: 3 hours a week over 18 weeks is 54 hours. Under the decided 14-week trimester at 56 hours, the same course runs exactly 4.0 weekly hours — a whole number, which the 54-hour figure never gave at either term length. So the column can stay on a weekly basis and simply be restated from 3 to 4. Still to decide before eight programmes populate the template: label the columns as weekly hours (4, 0, 4) or as total term hours (56, 0, 56), or carry both. See Open Item 6.
A33: D. OPEN ITEMS — TO BE RESOLVED, NOT GUESSED
A34: Open Item 1 — RESOLVED 9 Sep 2026 | B34: RESOLVED 9 Sep 2026 — 14 WEEKS. Decided by the Council of Programme Chairs. The contact-hour standard moves from 54 to 56 hours per 3-unit subject so that the week divides into whole periods: 56 hours over 14 weeks is 240 minutes a week, which splits into 2 x 120, 3 x 80 or 4 x 60 minutes. At 54 hours it would have been 231.43 minutes, which divides into nothing usable. 56 hours is 18.67 contact hours per unit against the CMO 27 & 30 floor of 14 — 33 per cent above it, better headroom than the old 54. COSTS OF THE DECISION, recorded so they are not lost: (1) the daily student load over four teaching days rises to 8.00 hours on a 24-unit term and 8.33 on the two 25-unit BSCRIM trimesters; (2) the proposed AY 2027-2028 calendar was drawn on FIFTEEN academic weeks and must be redrawn. TWO THINGS STILL OWED FOR THE DOSSIER: the Council meeting date and the resolution number covering this decision. Note also that the CMO 27 & 30 floor has only been read for BSA and BSAIS — each Chair still owes a check against their own PSG before the dossier states that 56 hours clears the floor for all eight.
A35: Open Item 2 | B35: Does the full CHED Region III GPR checklist apply to this application? The internal Preliminary Requirement checklist has 9 sections. The CHED Region III Citizen's Charter checklist for Application for Initial Permit / Government Recognition / COPC for Undergraduate Programs has 18, and items 1 and 5 to 10 match the internal checklist almost word for word - which strongly suggests the internal checklist was drawn from it. Nine requirements on the CHED list do not appear on the internal one at all: Articles of Incorporation and By-Laws; Transfer Certificate of Title, lease contract or proof of ownership of the school building; Certificate of Occupancy in the name of the HEI indicating educational purpose; physical facilities (site, floor area, buildings, classrooms, laboratories); equipment and instructional devices; support facilities (audio-visual room, sports, canteen, lounges); support services (guidance, medical and dental); NSTP coordinator and office; and the school bond of P6,000 plus an application fee of P4,000 and an inspection fee of P4,000. They are NOT in the tracker, because the internal checklist is the agreed source of truth and adding them would be a guess. If Region III confirms they apply, nine rows have to be added and several of them - occupancy certificate, facilities inventory - take real lead time. This is the single most consequential question on the list. [ Ask: MIS Head Francisco - tracker item 73, ask first ]
A36: Open Item 3 | B36: Which route, and therefore which library threshold? The CHED Region III charter distinguishes an INITIAL PERMIT (3,000 library collections) from RECOGNITION (5,000). The eight programmes already exist; only the delivery changes from semestral to trimestral. Confirm whether Region III treats a change in term system as a new permit application, an amendment to existing recognition, or something else - the answer sets the library target for item 68 and decides Open Item 2 with it. Note also that CHED's own charter cites no Memorandum Order for this checklist, only Section 8 of Republic Act No. 7722 as the general authority; so the absence of a CMO on the internal checklist is not an oversight by the college. [ Ask: MIS Head Francisco - tracker item 73 ]
A37: Open Item 4 | B37: Number of hard copy binders and the soft copy format required by CHED Region III on filing. Note that the charter also lists a school bond and application and inspection fees - confirm whether those are payable here (see Open Item 2). [ Ask: MIS Head Francisco - tracker item 73 ]
A38: Open Item 5 | B38: HIGHEST WORKLOAD IMPACT. Checklist item 7.4 - are course syllabi required for every course in all 8 programmes, or only for new and re-sequenced courses? The answer governs the 16 October deadline on items 15 to 62 and decides how serious Open Item 8 below really is. [ Ask: MIS Head Francisco - tracker item 73, due 25 Sep ]
A39: Open Item 6 | B39: THE TEMPLATE EXISTS BUT ITS HOURS COLUMNS ARE UNDEFINED. The BSCRIM submission of 3 Sep 2026 is the working template and its structure is settled (section C2). One thing is not: the Lec, Lab and Total Hrs columns are filled in as WEEKLY hours on the old semestral convention — a 3-unit lecture course shows 3 hours, which is 3 a week over 18 weeks, exactly 54. NARROWED 9 Sep 2026 by the Council's decision on Open Item 1: at 14 weeks and 56 hours the same course runs exactly 4.0 weekly hours, a whole number, so the arithmetic no longer fights the column. What remains is purely a labelling choice — restate the column as weekly hours (4, 0, 4), as total term hours (56, 0, 56), or carry both — and it must be settled before the other seven programmes populate the template, or all eight will need reworking. [ Ask: Vice Dean / Chairs - blocks 48 rows ]
